Workbook

Sheet Vendors
A1: Vendor | B1: Used for | C1: Where in code | D1: Billing unit | E1: Env var names | F1: Who pays
A2: OpenAI | B2: Managed LLM tiers (gpt-4.1-mini default, gpt-4.1 accurate, gpt-5 advanced); call QA; embeddings; realtime gpt-realtime-2 | C2: api/services/configuration/managed_tiers.py:251-253, 317-321, 360 | D2: per token | E2: PLATFORM_KEY_LLM_OPENAI, PLATFORM_KEY_LLM_OPENAI_REALTIME | F2: Platform
A3: Sarvam AI | B3: Managed LLM lite (sarvam-105b-conversations), STT default (saaras:v3), TTS default (bulbul:v3), translation, transcription | C3: managed_tiers.py:250,270,285; api/services/translation.py:28-94 | D3: LLM per token; STT per hour; TTS per 1k chars | E3: PLATFORM_KEY_STT_SARVAM, PLATFORM_KEY_TTS_SARVAM, PLATFORM_KEY_LLM_SARVAM | F3: Platform
A4: Google Gemini | B4: Realtime natural tier (gemini-3.1-flash-live-preview); builder; chat catalogue | C4: managed_tiers.py:327-331; api/services/pipecat/realtime/gemini_live.py:40 | D4: per token (audio tokens) | E4: PLATFORM_KEY_LLM_GOOGLE | F4: Platform when installed
A5: Anthropic | B5: Agent builder first preference (claude-sonnet-5); chat catalogue (Opus 5, Sonnet 5, Haiku 4.5) | C5: api/constants.py:704-722; api/services/agent_builder/client.py:553 | D5: per token | E5: PLATFORM_KEY_LLM_ANTHROPIC | F5: Platform when builder on / model pinned
A6: Deepgram | B6: Managed STT instant tier (Flux); transcription | C6: managed_tiers.py:278; api/services/gen_ai/transcription/providers.py:130 | D6: per minute | E6: PLATFORM_KEY_STT_DEEPGRAM | F6: Platform if key installed
A7: ElevenLabs | B7: Managed TTS global tier (eleven_flash_v2_5) | C7: managed_tiers.py:300 | D7: per 1k chars | E7: PLATFORM_KEY_TTS_ELEVENLABS | F7: Platform
A8: Smallest.ai | B8: Managed TTS natural tier (lightning_v3.1_pro) | C8: managed_tiers.py:297 | D8: per 1k chars | E8: PLATFORM_KEY_TTS_SMALLEST | F8: Platform
A9: Rumik AI | B9: Managed TTS basic tier (mulberry) | C9: managed_tiers.py:289 | D9: per 1k chars | E9: PLATFORM_KEY_TTS_RUMIK | F9: Platform
A10: Plivo | B10: Managed numbers, carriage, verification SMS | C10: api/constants.py:330-358; api/services/telephony/providers/plivo/provider.py:596 | D10: per minute; per number-month; per SMS | E10: PLATFORM_PLIVO_AUTH_ID, PLATFORM_PLIVO_AUTH_TOKEN, NUMBER_RENTAL_COST_PAISE | F10: Platform
A11: Twilio | B11: Verification SMS fallback; BYOK carrier; overseas reference carrier | C11: api/constants.py:1493; api/services/telephony/verification_sender.py:231 | D11: per minute; per SMS | E11: PLATFORM_TWILIO_ACCOUNT_SID, PLATFORM_TWILIO_AUTH_TOKEN | F11: Platform if configured
A12: Meta WhatsApp Cloud API | B12: Platform WhatsApp number send/receive | C12: api/services/messaging/platform_whatsapp.py:22-31; send.py:265 | D12: per template message | E12: WHATSAPP_ACCESS_TOKEN, WHATSAPP_PHONE_NUMBER_ID | F12: Platform
... A21: SMTP relay (vendor unnamed) | B21: Transactional email | C21: api/services/messaging/email.py:18 | D21: per email | E21: SMTP_HOST, SMTP_USERNAME, SMTP_PASSWORD | F21: Platform
A22: Self-hosted (no vendor bill) | B22: Postgres+pgvector, Redis/ARQ, FalkorDB, Gotenberg, Tesseract/Docling, sandbox, coturn, nginx, cloudflared | C22: docker-compose.yaml | D22: infra only | F22: Infra
A23: BYOK only (no platform bill) | B23: OpenRouter, Groq, Cerebras, DeepSeek, Mistral, Fireworks, Azure, Bedrock, Cartesia, Speechmatics, Gladia, AssemblyAI, Vonage, Telnyx, Cloudonix, Vobiz, Exotel/Smartflo import | C23: api/services/pipecat/service_factory.py | D23: customer's account | F23: Customer
A25: Full inventory with file:line for every hit: step1_inventory.md in this folder.

Sheet Unit prices
A1: Key | B1: Vendor | C1: Item | D1: Unit | E1: Value | F1: Currency | G1: Label | H1: Source URL | I1: Date checked | J1: Note
A2: fx | B2: RBI / FBIL | C2: USD to INR reference rate, 28 Sep 2026 (latest published before 29 Sep) | D2: INR per USD | E2: 95.968 | F2: INR | G2: vendor price | H2: https://www.fbil.org.in/ (value read from CEIC, which republishes the FBIL/RBI series; the FBIL page itself could not be fetched) | I2: 2026-09-28 | J2: UNVERIFIED on the official page: fbil.org.in timed out and the RBI archive needs a form post. Confirm at fbil.org.in before quoting. The billing code falls back to 96.00 (api/services/billing/money.py:49) and stores its own rate history from Frankfurter.
A3: gst | B3: GoI | C3: GST on foreign vendor bills under reverse charge (creditable ITC; cash-flow only) | D3: share | E3: 0.18 | G3: vendor price | H3: https://cbic-gst.gov.in/ | I3: 2026-09-29 | J3: Not added to unit costs: input tax credit is claimed. It is a cash-flow timing item on every foreign invoice.
A4: gpt41mini_in | B4: OpenAI | C4: gpt-4.1-mini input (managed default tier) | D4: USD per 1M tokens | E4: 0.4 | F4: USD | G4: code constant | H4: https://developers.openai.com/api/docs/pricing | I4: 2026-09-14 | J4: From the code rate book (default_rates.py, checked 14 Sep 2026). The 29 Sep survey found the page now leads with the gpt-5 family; gpt-4.1-mini was not re-read. Re-verify.
A5: gpt41mini_cached | B5: OpenAI | C5: gpt-4.1-mini cached input | D5: USD per 1M tokens | E5: 0.1 | F5: USD | G5: code constant | H5: https://developers.openai.com/api/docs/pricing | I5: 2026-09-14 | J5: Code rate book split rows (cached share 0.25 of input for gpt-4.1 family per OpenAI).
A6: gpt41mini_out | B6: OpenAI | C6: gpt-4.1-mini output | D6: USD per 1M tokens | E6: 1.6 | F6: USD | G6: code constant | H6: https://developers.openai.com/api/docs/pricing | I6: 2026-09-14
A7: gpt41_in | B7: OpenAI | C7: gpt-4.1 input (managed accurate tier) | D7: USD per 1M tokens | E7: 2 | F7: USD | G7: code constant | H7: https://developers.openai.com/api/docs/pricing | I7: 2026-09-14 | J7: Code rate book; not re-read on 29 Sep.
A8: gpt41_cached | B8: OpenAI | C8: gpt-4.1 cached input | D8: USD per 1M tokens | E8: 0.5 | F8: USD | G8: code constant | H8: https://developers.openai.com/api/docs/pricing | I8: 2026-09-14
A9: gpt41_out | B9: OpenAI | C9: gpt-4.1 output | D9: USD per 1M tokens | E9: 8 | F9: USD | G9: code constant | H9: https://developers.openai.com/api/docs/pricing | I9: 2026-09-14
A10: gpt5_in | B10: OpenAI | C10: gpt-5 input | D10: USD per 1M tokens | E10: 1.25 | F10: USD | G10: vendor price | H10: https://developers.openai.com/api/docs/pricing | I10: 2026-09-29
A11: gpt5_cached | B11: OpenAI | C11: gpt-5 cached input | D11: USD per 1M tokens | E11: 0.125 | F11: USD | G11: vendor price | H11: https://developers.openai.com/api/docs/pricing | I11: 2026-09-29
A12: gpt5_out | B12: OpenAI | C12: gpt-5 output | D12: USD per 1M tokens | E12: 10 | F12: USD | G12: vendor price | H12: https://developers.openai.com/api/docs/pricing | I12: 2026-09-29
A13: gpt5nano_in | B13: OpenAI | C13: gpt-5-nano input | D13: USD per 1M tokens | E13: 0.05 | F13: USD | G13: vendor price | H13: https://developers.openai.com/api/docs/pricing | I13: 2026-09-29
A14: gpt5nano_cached | B14: OpenAI | C14: gpt-5-nano cached input | D14: USD per 1M tokens | E14: 0.005 | F14: USD | G14: vendor price | H14: https://developers.openai.com/api/docs/pricing | I14: 2026-09-29
A15: gpt5nano_out | B15: OpenAI | C15: gpt-5-nano output | D15: USD per 1M tokens | E15: 0.4 | F15: USD | G15: vendor price | H15: https://developers.openai.com/api/docs/pricing | I15: 2026-09-29
A16: sonnet5_in | B16: Anthropic | C16: claude-sonnet-5 input (agent builder default) | D16: USD per 1M tokens | E16: 2 | F16: USD | G16: vendor price | H16: https://platform.claude.com/docs/en/about-claude/pricing | I16: 2026-09-29 | J16: Page notes the planned rise to $3/$15 was cancelled; $2/$10 stands.
A17: sonnet5_cached | B17: Anthropic | C17: claude-sonnet-5 cached read | D17: USD per 1M tokens | E17: 0.2 | F17: USD | G17: vendor price | H17: https://platform.claude.com/docs/en/about-claude/pricing | I17: 2026-09-29 | J17: Cache write is 1.25x input (5 min) and is not modelled: it applies once per conversation.
A18: sonnet5_out | B18: Anthropic | C18: claude-sonnet-5 output | D18: USD per 1M tokens | E18: 10 | F18: USD | G18: vendor price | H18: https://platform.claude.com/docs/en/about-claude/pricing | I18: 2026-09-29
A19: opus5_in | B19: Anthropic | C19: claude-opus-5 input (dearest model in the chat catalogue) | D19: USD per 1M tokens | E19: 5 | F19: USD | G19: code constant | H19: https://platform.claude.com/docs/en/about-claude/pricing | I19: 2026-09-14 | J19: Code rate book. The official page on 29 Sep lists Opus 5.5 at $4/$20 and no longer lists Opus 5; the higher code figure is kept as the worst case.
A20: opus5_cached | B20: Anthropic | C20: claude-opus-5 cached read | D20: USD per 1M tokens | E20: 0.5 | F20: USD | G20: code constant | H20: https://platform.claude.com/docs/en/about-claude/pricing | I20: 2026-09-14
A21: opus5_out | B21: Anthropic | C21: claude-opus-5 output | D21: USD per 1M tokens | E21: 25 | F21: USD | G21: code constant | H21: https://platform.claude.com/docs/en/about-claude/pricing | I21: 2026-09-14
A22: gemini25flash_in | B22: Google | C22: gemini-2.5-flash input | D22: USD per 1M tokens | E22: 0.3 | F22: USD | G22: vendor price | H22: https://ai.google.dev/gemini-api/docs/pricing | I22: 2026-09-29
A23: gemini25flash_cached | B23: Google | C23: gemini-2.5-flash cached input | D23: USD per 1M tokens | E23: 0.03 | F23: USD | G23: vendor price | H23: https://ai.google.dev/gemini-api/docs/pricing | I23: 2026-09-29 | J23: Plus $1.00 per 1M tokens per hour of cache storage, not modelled.
A24: gemini25flash_out | B24: Google | C24: gemini-2.5-flash output | D24: USD per 1M tokens | E24: 2.5 | F24: USD | G24: vendor price | H24: https://ai.google.dev/gemini-api/docs/pricing | I24: 2026-09-29
A25: sarvam105b_in | B25: Sarvam | C25: sarvam-105b input | D25: INR per 1M tokens | E25: 29.28 | F25: INR | G25: vendor price | H25: https://docs.sarvam.ai/api-reference-docs/pricing | I25: 2026-09-29
A26: sarvam105b_cached | B26: Sarvam | C26: sarvam-105b cached input | D26: INR per 1M tokens | E26: 10.98 | F26: INR | G26: vendor price | H26: https://docs.sarvam.ai/api-reference-docs/pricing | I26: 2026-09-29
A27: sarvam105b_out | B27: Sarvam | C27: sarvam-105b output | D27: INR per 1M tokens | E27: 73.2 | F27: INR | G27: vendor price | H27: https://docs.sarvam.ai/api-reference-docs/pricing | I27: 2026-09-29
A28: embed_small | B28: OpenAI | C28: text-embedding-3-small | D28: USD per 1M tokens | E28: 0.02 | F28: USD | G28: vendor price | H28: https://developers.openai.com/api/docs/pricing | I28: 2026-09-29
A29: sarvam_stt_hr | B29: Sarvam | C29: saaras:v3 / saarika streaming STT | D29: INR per hour | E29: 30 | F29: INR | G29: vendor price | H29: https://docs.sarvam.ai/api-reference-docs/pricing | I29: 2026-09-29
A30: sarvam_tts_10k | B30: Sarvam | C30: bulbul:v3 TTS | D30: INR per 10k characters | E30: 30 | F30: INR | G30: vendor price | H30: https://docs.sarvam.ai/api-reference-docs/pricing | I30: 2026-09-29
A31: sarvam_translate_10k | B31: Sarvam | C31: Translate | D31: INR per 10k characters | E31: 20 | F31: INR | G31: vendor price | H31: https://docs.sarvam.ai/api-reference-docs/pricing | I31: 2026-09-29 | J31: Tiers to Rs0.0045 and Rs0.004 a character at volume.
A32: deepgram_flux_min | B32: Deepgram | C32: Flux multilingual streaming STT (managed instant tier) | D32: USD per minute | E32: 0.0078 | F32: USD | G32: code constant | H32: https://deepgram.com/pricing | I32: 2026-09-14 | J32: Code rate book. The 29 Sep survey read Nova-3 multilingual streaming at $0.0058 (Growth $0.0050); Flux was not on the page read. Re-verify.
A33: deepgram_batch_min | B33: Deepgram | C33: Nova-3 pre-recorded (batch) STT | D33: USD per minute | E33: 0.0052 | F33: USD | G33: vendor price | H33: https://deepgram.com/pricing | I33: 2026-09-29
A34: eleven_flash_1k | B34: ElevenLabs | C34: Flash v2.5 TTS, effective rate | D34: USD per 1k characters | E34: 0.05 | F34: USD | G34: assumption | H34: https://elevenlabs.io/pricing/api | I34: 2026-09-29 | J34: Official page on 29 Sep: pay-as-you-go $0.022/1k on a promotion to 12 Oct 2026, list $0.08/1k; Scale plan $299 for 9M chars = $0.033/1k; Business $990 for 27.18M = $0.036/1k. Our plan is unknown, so the code book's $0.05 is kept as a mid figure. Open question.
A35: smallest_pro_10k | B35: Smallest.ai | C35: Lightning v3.1 Pro TTS (managed natural tier) | D35: USD per 10k characters | E35: 0.195 | F35: USD | G35: code constant | H35: https://smallest.ai/pricing/models | I35: 2026-09-14 | J35: Code rate book; not re-read on 29 Sep.
A36: rumik_1k | B36: Rumik | C36: Mulberry TTS (managed basic tier) | D36: INR per 1k characters | E36: 0.5 | F36: INR | G36: code constant | H36: https://rumik.ai/pricing | I36: 2026-09-14 | J36: Code rate book, launch pricing; not re-read on 29 Sep.
A37: gemini_live_in | B37: Google | C37: Gemini Live audio input | D37: USD per 1M tokens | E37: 3 | F37: USD | G37: vendor price | H37: https://ai.google.dev/gemini-api/docs/pricing | I37: 2026-09-29 | J37: Gemini 3.8 Live and 2.5 Flash native audio both $3.00 audio in.
A38: gemini_live_cached | B38: Google | C38: Gemini Live cached audio input | D38: USD per 1M tokens | E38: 0.3 | F38: USD | G38: code constant | H38: https://ai.google.dev/gemini-api/docs/pricing | I38: 2026-07 | J38: Code rate book (realtime_rates.py); the page read on 29 Sep does not show a cached audio price for Live. Re-verify.
A39: gemini_live_out | B39: Google | C39: Gemini Live audio output | D39: USD per 1M tokens | E39: 12 | F39: USD | G39: vendor price | H39: https://ai.google.dev/gemini-api/docs/pricing | I39: 2026-09-29
A40: gemini_live_tps_in | B40: Google | C40: audio tokens per second, input | D40: tokens per second | E40: 32 | G40: code constant | H40: https://ai.google.dev/gemini-api/docs/pricing | I40: 2026-07 | J40: realtime_rates.py; Google documents 32 tokens a second of audio.
...

Sheet Measured usage
A1: Key | B1: Activity | C1: Metric | D1: Value | E1: Label | F1: Sample (n) | G1: Source | H1: Note
A2: sys_prompt_tokens | B2: Decibyl chat | C2: System prompt tokens (all flags on) | D2: 2523 | E2: measured | F2: 1 | G2: Measured locally: api/services/workflow/decibyl.py prompt rendered, cl100k_base tokenizer | H2: Grows with memory and connected apps; this is the floor.
A3: tools_schema_tokens | B3: Decibyl chat | C3: Tool schema tokens (24 office tools) | D3: 5674 | E3: measured | F3: 1 | G3: Measured locally: tool JSON schemas, cl100k_base | H3: Sent on every turn.
A4: history_tokens_med | B4: Decibyl chat | C4: Conversation history + memory tokens, median | D4: 3000 | E4: assumption | F4: 0 | G4: No per-turn token receipts were readable (superadmin only); see Open questions | H4: Sensitivity: p90 uses 8,000.
A5: history_tokens_p90 | B5: Decibyl chat | C5: Conversation history + memory tokens, p90 | D5: 8000 | E5: assumption | F5: 0 | G5: As above
A6: chat_out_med | B6: Decibyl chat | C6: Output tokens per reply, median | D6: 300 | E6: assumption | F6: 0 | G6: Typical chat reply of 150-250 words
A7: chat_out_p90 | B7: Decibyl chat | C7: Output tokens per reply, p90 | D7: 900 | E7: assumption | F7: 0 | G7: Long reply or a drafted email
A8: chat_tool_calls | B8: Decibyl chat | C8: Tool calls per chat message, mean | D8: 0.6 | E8: assumption | F8: 0 | G8: 200 exported runs show nodes_visited 1-3 per textchat run; a plain question is 0, an action is 1-2
A9: cache_hit | B9: All LLM | C9: Prompt-cache hit rate on input tokens (base) | D9: 0.7 | E9: assumption | F9: 0 | G9: The stable prefix (system prompt + tools = 8,197 tokens) is 73% of a median input; OpenAI caches prefixes over 1,024 tokens automatically | H9: No measured hit rate exists: call_turn_metrics.cached_tokens is superadmin-only. Sensitivity runs 0.5 and 0.9.
A10: builder_in | B10: Agent builder | C10: Input tokens per builder message | D10: 9000 | E10: assumption | F10: 0 | G10: Builder prompt + the agent draft resent each turn; not measured (AGENT_BUILDER_ENABLED is off in production)
A11: builder_out | B11: Agent builder | C11: Output tokens per builder message | D11: 1200 | E11: assumption | F11: 0 | G11: A builder turn rewrites part of the draft
A12: task_llm_turns | B12: Task run | C12: LLM turns per task run | D12: 3 | E12: assumption | F12: 0 | G12: Exported runs: textchat runs visit 1-3 nodes; a task with tools takes plan, act, report
A13: task_tool_calls | B13: Task run | C13: Tool calls per task run | D13: 2 | E13: assumption | F13: 0 | G13: As above
A14: routine_llm_turns | B14: Routine run | C14: LLM turns per routine run | D14: 1 | E14: measured | F14: 20 | G14: finance/costing-2026-10/raw/usage_runs*.json: 'Inbox Brief' routine runs, nodes_visited ['Start'], median 7 s on gpt-5-nano
A15: routine_tool_calls | B15: Routine run | C15: Tool calls per routine run | D15: 1 | E15: measured | F15: 20 | G15: Same runs: one Gmail fetch each (usage_review.json summaries)
A16: trigger_llm_turns | B16: Trigger run | C16: LLM turns per trigger run | D16: 1 | E16: assumption | F16: 0 | G16: A trigger is one reply to one event
A17: kb_pages | B17: Knowledge ingest | C17: Pages per ingested document (reference: 10-page PDF) | D17: 10 | E17: assumption | F17: 0 | G17: Prompt scenario C
A18: kb_chars_per_page | B18: Knowledge ingest | C18: Characters per page | D18: 3000 | E18: code constant | F18: 0 | G18: api/services/billing/knowledge_pages.py:45 CHARS_PER_PAGE
A19: kb_tokens_per_char | B19: Knowledge ingest | C19: Tokens per character (English prose) | D19: 0.25 | E19: assumption | F19: 0 | G19: cl100k: about 4 characters per token
A20: kb_answer_ctx | B20: Knowledge answer | C20: Retrieved context tokens added to the reply | D20: 3000 | E20: assumption | F20: 0 | G20: Top-k chunks; the code caps chat_context_tokens per plan (plan_limits.py)
A21: kb_query_tokens | B21: Knowledge answer | C21: Query embedding tokens | D21: 40 | E21: assumption | F21: 0
A22: calls_30d | B22: Voice | C22: Calls in the last 30 days | D22: 301 | E22: measured | F22: 301 | G22: finance/costing-2026-10/raw/usage_calls.json totals.calls (31 Aug to 29 Sep 2026)
A23: billable_min_30d | B23: Voice | C23: Billable minutes in the last 30 days | D23: 120.66667 | E23: measured | F23: 301 | G23: finance/costing-2026-10/raw/usage_calls.json totals.billable_seconds / 60
A24: charged_30d_inr | B24: Voice | C24: Charged for those calls (INR) | D24: 458.04 | E24: measured | F24: 301 | G24: finance/costing-2026-10/raw/usage_calls.json totals.charged_paise / 100
A25: stt_charged_30d | B25: Voice | C25: STT charged, last 30 days (INR) | D25: 95.11 | E25: measured | F25: 301 | G25: finance/costing-2026-10/raw/usage_spend.json series, stt, 31 Aug to 29 Sep
A26: tts_charged_30d | B26: Voice | C26: TTS charged, last 30 days (INR) | D26: 179.22 | E26: measured | F26: 301 | G26: finance/costing-2026-10/raw/usage_spend.json series, tts
A27: llm_charged_30d | B27: All | C27: LLM charged, last 30 days (INR, voice and text together) | D27: 77.12 | E27: measured | F27: 301 | G27: finance/costing-2026-10/raw/usage_spend.json series, llm
A28: markup_stt | B28: Billing code | C28: STT markup applied when charging | D28: 1.3 | E28: code constant | F28: 0 | G28: api/services/billing/markup.py:568-583 (KAN-54)
A29: markup_tts | B29: Billing code | C29: TTS markup applied when charging | D29: 1.8 | E29: code constant | F29: 0 | G29: markup.py:568-583
A30: markup_llm | B30: Billing code | C30: LLM markup applied when charging | D30: 2 | E30: code constant | F30: 0 | G30: markup.py:568-583
A31: turns_per_min | B31: Voice | C31: LLM turns per minute of call | D31: 6 | E31: code constant | F31: 0 | G31: api/services/billing/realtime_pricing.py:91 seconds_per_turn = 10 | H31: Same shape the code prices realtime calls with.
A32: voice_prompt_tokens | B32: Voice | C32: Agent system prompt + tools per turn (tokens) | D32: 1800 | E32: assumption | F32: 0 | G32: A voice agent carries a shorter prompt and 2-4 tools; not measured
A33: voice_transcript_tok_per_min | B33: Voice | C33: Transcript tokens added per minute of call | D33: 220 | E33: assumption | F33: 0 | G33: About 150 spoken words a minute, both sides, at 1.4 tokens a word
A34: voice_out_tok_per_turn | B34: Voice | C34: Output tokens per turn (spoken reply) | D34: 45 | E34: assumption | F34: 0 | G34: A 2-3 sentence spoken reply
A35: tts_cpm | B35: Voice | C35: TTS characters per minute of call (base) | D35: 450 | E35: assumption | F35: 0 | G35: Agent talks 45% of the time (realtime_pricing.py:95) at about 1,000 chars a minute of speech; the 30-day charged TTS backs out to about 275 (see tts_cpm_measured). Sensitivity runs 350 and 600.
A36: stt_min_per_call_min | B36: Voice | C36: STT minutes billed per call minute | D36: 1 | E36: assumption | F36: 0 | G36: Streaming STT runs for the whole call, both silences and speech
A37: call_len_med_s | B37: Voice | C37: Call length, median (seconds) | D37: 24.1 | E37: measured | F37: 301 | G37: finance/costing-2026-10/raw/usage_calls.json totals.average_seconds | H37: 237 of 301 calls were under 30 s: demo and test traffic, not a customer's pattern.
A38: call_len_ref_s | B38: Voice | C38: Reference call length for realtime pricing (seconds) | D38: 180 | E38: code constant | F38: 0 | G38: realtime_pricing.py:90 duration_seconds; prompt scenario G is also 3 minutes
A39: agent_talk_share | B39: Voice | C39: Share of the call the agent is speaking | D39: 0.45 | E39: code constant | F39: 0 | G39: realtime_pricing.py:95
A40: caller_talk_share | B40: Voice | C40: Share of the call the caller is speaking | D40: 0.3 | E40: code constant | F40: 0 | G40: realtime_pricing.py:98
...

Sheet Unit costs
A1: Levers (base case; the Sensitivity sheet overrides these per scenario)
A2: INR per USD | B2: ='Unit prices'!$E$2
A3: Model price multiplier | B3: 1
A4: Prompt-cache hit rate | B4: ='Measured usage'!$D$9
A5: TTS characters per minute | B5: ='Measured usage'!$D$35
A6: Telephony multiplier | B6: 1
A7: Price multiple on cost (proposed) | B7: 3
A8: Minimum credits per action (proposed) | B8: 0.5
A9: 1 credit, India (INR) | B9: 1
A10: 1 credit, global (USD) | B10: 0.012
A13: Activity | B13: Unit | C13: Case | D13: STT (USD) | E13: LLM (USD) | F13: TTS (USD) | G13: Telephony (USD) | H13: Realtime (USD) | I13: Tools (USD) | J13: Embed (USD) | K13: Meta (USD) | L13: Data (USD) | M13: Infra (USD) | N13: Sarvam (USD) | O13: Total USD | P13: Total INR | Q13: Credits at cost x multiple (min applies) | R13: Price INR (credits x 1) | S13: Gross margin | T13: Below-minimum? | U13: Margin < 60%?
A14: 1a. Chat message, default model (gpt-4.1-mini) | B14: per message | C14: median | E14: ='Unit costs'!$B$3*(('Measured usage'!$D$2+'Measured usage'!$D$3+'Measured usage'!$D$4)*((1-'Unit costs'!$B$4)*'Unit prices'!$E$4+'Unit costs'!$B$4*'Unit prices'!$E$5)+'Measured usage'!$D$6*'Unit prices'!$E$6)/1000000 | I14: ='Measured usage'!$D$8*'Unit prices'!$E$56 | O14: =SUM(D14:N14) | P14: =O14*'Unit costs'!$B$2 | Q14: =MAX('Unit costs'!$B$8,P14*'Unit costs'!$B$7/'Unit costs'!$B$9) | R14: =Q14*'Unit costs'!$B$9 | S14: =IF(R14>0,1-P14/R14,0) | T14: =IF(P14*'Unit costs'!$B$7<'Unit costs'!$B$8*'Unit costs'!$B$9,"yes","") | U14: =IF(S14<0.6,"yes","")
A15: 1a. Chat message, default model (gpt-4.1-mini) | B15: per message | C15: p90 | E15: ='Unit costs'!$B$3*(('Measured usage'!$D$2+'Measured usage'!$D$3+'Measured usage'!$D$5)*((1-'Unit costs'!$B$4)*'Unit prices'!$E$4+'Unit costs'!$B$4*'Unit prices'!$E$5)+'Measured usage'!$D$7*'Unit prices'!$E$6)/1000000 | I15: ='Measured usage'!$D$8*'Unit prices'!$E$56 | O15: =SUM(D15:N15) | P15: =O15*'Unit costs'!$B$2 | Q15: =MAX('Unit costs'!$B$8,P15*'Unit costs'!$B$7/'Unit costs'!$B$9) | R15: =Q15*'Unit costs'!$B$9 | S15: =IF(R15>0,1-P15/R15,0) | T15: =IF(P15*'Unit costs'!$B$7<'Unit costs'!$B$8*'Unit costs'!$B$9,"yes","") | U15: =IF(S15<0.6,"yes","")
A16: 1b. Chat message, premium model (gpt-5) | B16: per message | C16: median | E16: ='Unit costs'!$B$3*(('Measured usage'!$D$2+'Measured usage'!$D$3+'Measured usage'!$D$4)*((1-'Unit costs'!$B$4)*'Unit prices'!$E$10+'Unit costs'!$B$4*'Unit prices'!$E$11)+'Measured usage'!$D$6*'Unit prices'!$E$12)/1000000 | I16: ='Measured usage'!$D$8*'Unit prices'!$E$56 | O16: =SUM(D16:N16) | P16: =O16*'Unit costs'!$B$2 | Q16: =MAX('Unit costs'!$B$8,P16*'Unit costs'!$B$7/'Unit costs'!$B$9) | R16: =Q16*'Unit costs'!$B$9 | S16: =IF(R16>0,1-P16/R16,0) | T16: =IF(P16*'Unit costs'!$B$7<'Unit costs'!$B$8*'Unit costs'!$B$9,"yes","") | U16: =IF(S16<0.6,"yes","")
A17: 1b. Chat message, premium model (gpt-5) | B17: per message | C17: p90 | E17: ='Unit costs'!$B$3*(('Measured usage'!$D$2+'Measured usage'!$D$3+'Measured usage'!$D$5)*((1-'Unit costs'!$B$4)*'Unit prices'!$E$10+'Unit costs'!$B$4*'Unit prices'!$E$11)+'Measured usage'!$D$7*'Unit prices'!$E$12)/1000000 | I17: ='Measured usage'!$D$8*'Unit prices'!$E$56 | O17: =SUM(D17:N17) | P17: =O17*'Unit costs'!$B$2 | Q17: =MAX('Unit costs'!$B$8,P17*'Unit costs'!$B$7/'Unit costs'!$B$9) | R17: =Q17*'Unit costs'!$B$9 | S17: =IF(R17>0,1-P17/R17,0) | T17: =IF(P17*'Unit costs'!$B$7<'Unit costs'!$B$8*'Unit costs'!$B$9,"yes","") | U17: =IF(S17<0.6,"yes","")
A18: 1c. Chat message, dearest catalogue model (claude-opus-5) | B18: per message | C18: median | E18: ='Unit costs'!$B$3*(('Measured usage'!$D$2+'Measured usage'!$D$3+'Measured usage'!$D$4)*((1-'Unit costs'!$B$4)*'Unit prices'!$E$19+'Unit costs'!$B$4*'Unit prices'!$E$20)+'Measured usage'!$D$6*'Unit prices'!$E$21)/1000000 | I18: ='Measured usage'!$D$8*'Unit prices'!$E$56 | O18: =SUM(D18:N18) | P18: =O18*'Unit costs'!$B$2 | Q18: =MAX('Unit costs'!$B$8,P18*'Unit costs'!$B$7/'Unit costs'!$B$9) | R18: =Q18*'Unit costs'!$B$9 | S18: =IF(R18>0,1-P18/R18,0) | T18: =IF(P18*'Unit costs'!$B$7<'Unit costs'!$B$8*'Unit costs'!$B$9,"yes","") | U18: =IF(S18<0.6,"yes","")
A19: 1c. Chat message, dearest catalogue model (claude-opus-5) | B19: per message | C19: p90 | E19: ='Unit costs'!$B$3*(('Measured usage'!$D$2+'Measured usage'!$D$3+'Measured usage'!$D$5)*((1-'Unit costs'!$B$4)*'Unit prices'!$E$19+'Unit costs'!$B$4*'Unit prices'!$E$20)+'Measured usage'!$D$7*'Unit prices'!$E$21)/1000000 | I19: ='Measured usage'!$D$8*'Unit prices'!$E$56 | O19: =SUM(D19:N19) | P19: =O19*'Unit costs'!$B$2 | Q19: =MAX('Unit costs'!$B$8,P19*'Unit costs'!$B$7/'Unit costs'!$B$9) | R19: =Q19*'Unit costs'!$B$9 | S19: =IF(R19>0,1-P19/R19,0) | T19: =IF(P19*'Unit costs'!$B$7<'Unit costs'!$B$8*'Unit costs'!$B$9,"yes","") | U19: =IF(S19<0.6,"yes","")
A20: 1d. Chat message, cheapest catalogue model (gpt-5-nano) | B20: per message | C20: median | E20: ='Unit costs'!$B$3*(('Measured usage'!$D$2+'Measured usage'!$D$3+'Measured usage'!$D$4)*((1-'Unit costs'!$B$4)*'Unit prices'!$E$13+'Unit costs'!$B$4*'Unit prices'!$E$14)+'Measured usage'!$D$6*'Unit prices'!$E$15)/1000000 | I20: ='Measured usage'!$D$8*'Unit prices'!$E$56 | O20: =SUM(D20:N20) | P20: =O20*'Unit costs'!$B$2 | Q20: =MAX('Unit costs'!$B$8,P20*'Unit costs'!$B$7/'Unit costs'!$B$9) | R20: =Q20*'Unit costs'!$B$9 | S20: =IF(R20>0,1-P20/R20,0) | T20: =IF(P20*'Unit costs'!$B$7<'Unit costs'!$B$8*'Unit costs'!$B$9,"yes","") | U20: =IF(S20<0.6,"yes","")
A21: 1d. Chat message, cheapest catalogue model (gpt-5-nano) | B21: per message | C21: p90 | E21: ='Unit costs'!$B$3*(('Measured usage'!$D$2+'Measured usage'!$D$3+'Measured usage'!$D$5)*((1-'Unit costs'!$B$4)*'Unit prices'!$E$13+'Unit costs'!$B$4*'Unit prices'!$E$14)+'Measured usage'!$D$7*'Unit prices'!$E$15)/1000000 | I21: ='Measured usage'!$D$8*'Unit prices'!$E$56 | O21: =SUM(D21:N21) | P21: =O21*'Unit costs'!$B$2 | Q21: =MAX('Unit costs'!$B$8,P21*'Unit costs'!$B$7/'Unit costs'!$B$9) | R21: =Q21*'Unit costs'!$B$9 | S21: =IF(R21>0,1-P21/R21,0) | T21: =IF(P21*'Unit costs'!$B$7<'Unit costs'!$B$8*'Unit costs'!$B$9,"yes","") | U21: =IF(S21<0.6,"yes","")
A22: 2. Agent-building message (claude-sonnet-5) | B22: per message | C22: median | E22: ='Unit costs'!$B$3*('Measured usage'!$D$10*((1-'Unit costs'!$B$4)*'Unit prices'!$E$16+'Unit costs'!$B$4*'Unit prices'!$E$17)+'Measured usage'!$D$11*'Unit prices'!$E$18)/1000000 | O22: =SUM(D22:N22) | P22: =O22*'Unit costs'!$B$2 | Q22: =MAX('Unit costs'!$B$8,P22*'Unit costs'!$B$7/'Unit costs'!$B$9) | R22: =Q22*'Unit costs'!$B$9 | S22: =IF(R22>0,1-P22/R22,0) | T22: =IF(P22*'Unit costs'!$B$7<'Unit costs'!$B$8*'Unit costs'!$B$9,"yes","") | U22: =IF(S22<0.6,"yes","")
A23: 2. Agent-building message (claude-sonnet-5) | B23: per message | C23: p90 | E23: ='Unit costs'!$B$3*(2*'Measured usage'!$D$10*((1-'Unit costs'!$B$4)*'Unit prices'!$E$16+'Unit costs'!$B$4*'Unit prices'!$E$17)+2*'Measured usage'!$D$11*'Unit prices'!$E$18)/1000000 | O23: =SUM(D23:N23) | P23: =O23*'Unit costs'!$B$2 | Q23: =MAX('Unit costs'!$B$8,P23*'Unit costs'!$B$7/'Unit costs'!$B$9) | R23: =Q23*'Unit costs'!$B$9 | S23: =IF(R23>0,1-P23/R23,0) | T23: =IF(P23*'Unit costs'!$B$7<'Unit costs'!$B$8*'Unit costs'!$B$9,"yes","") | U23: =IF(S23<0.6,"yes","")
A24: 3a. Task run (3 LLM turns + 2 tool calls, gpt-4.1-mini) | B24: per run | C24: median | E24: ='Measured usage'!$D$12*'Unit costs'!$B$3*(('Measured usage'!$D$2+'Measured usage'!$D$3+'Measured usage'!$D$4)*((1-'Unit costs'!$B$4)*'Unit prices'!$E$4+'Unit costs'!$B$4*'Unit prices'!$E$5)+'Measured usage'!$D$6*'Unit prices'!$E$6)/1000000 | I24: ='Measured usage'!$D$13*'Unit prices'!$E$56 | O24: =SUM(D24:N24) | P24: =O24*'Unit costs'!$B$2 | Q24: =MAX('Unit costs'!$B$8,P24*'Unit costs'!$B$7/'Unit costs'!$B$9) | R24: =Q24*'Unit costs'!$B$9 | S24: =IF(R24>0,1-P24/R24,0) | T24: =IF(P24*'Unit costs'!$B$7<'Unit costs'!$B$8*'Unit costs'!$B$9,"yes","") | U24: =IF(S24<0.6,"yes","")
A25: 3a. Task run (3 LLM turns + 2 tool calls, gpt-4.1-mini) | B25: per run | C25: p90 | E25: =2*'Measured usage'!$D$12*'Unit costs'!$B$3*(('Measured usage'!$D$2+'Measured usage'!$D$3+'Measured usage'!$D$5)*((1-'Unit costs'!$B$4)*'Unit prices'!$E$4+'Unit costs'!$B$4*'Unit prices'!$E$5)+'Measured usage'!$D$7*'Unit prices'!$E$6)/1000000 | I25: =2*'Measured usage'!$D$13*'Unit prices'!$E$56 | O25: =SUM(D25:N25) | P25: =O25*'Unit costs'!$B$2 | Q25: =MAX('Unit costs'!$B$8,P25*'Unit costs'!$B$7/'Unit costs'!$B$9) | R25: =Q25*'Unit costs'!$B$9 | S25: =IF(R25>0,1-P25/R25,0) | T25: =IF(P25*'Unit costs'!$B$7<'Unit costs'!$B$8*'Unit costs'!$B$9,"yes","") | U25: =IF(S25<0.6,"yes","")
A26: 3b. Routine run (1 turn + 1 tool call, gpt-5-nano as run today) | B26: per run | C26: median | E26: ='Measured usage'!$D$14*'Unit costs'!$B$3*(('Measured usage'!$D$2+'Measured usage'!$D$3+'Measured usage'!$D$4)*((1-'Unit costs'!$B$4)*'Unit prices'!$E$13+'Unit costs'!$B$4*'Unit prices'!$E$14)+'Measured usage'!$D$6*'Unit prices'!$E$15)/1000000 | I26: ='Measured usage'!$D$15*'Unit prices'!$E$56 | O26: =SUM(D26:N26) | P26: =O26*'Unit costs'!$B$2 | Q26: =MAX('Unit costs'!$B$8,P26*'Unit costs'!$B$7/'Unit costs'!$B$9) | R26: =Q26*'Unit costs'!$B$9 | S26: =IF(R26>0,1-P26/R26,0) | T26: =IF(P26*'Unit costs'!$B$7<'Unit costs'!$B$8*'Unit costs'!$B$9,"yes","") | U26: =IF(S26<0.6,"yes","")
A27: 3b. Routine run (1 turn + 1 tool call, gpt-5-nano as run today) | B27: per run | C27: p90 | E27: ='Measured usage'!$D$14*'Unit costs'!$B$3*(('Measured usage'!$D$2+'Measured usage'!$D$3+'Measured usage'!$D$5)*((1-'Unit costs'!$B$4)*'Unit prices'!$E$4+'Unit costs'!$B$4*'Unit prices'!$E$5)+'Measured usage'!$D$7*'Unit prices'!$E$6)/1000000 | I27: ='Measured usage'!$D$15*'Unit prices'!$E$56 | O27: =SUM(D27:N27) | P27: =O27*'Unit costs'!$B$2 | Q27: =MAX('Unit costs'!$B$8,P27*'Unit costs'!$B$7/'Unit costs'!$B$9) | R27: =Q27*'Unit costs'!$B$9 | S27: =IF(R27>0,1-P27/R27,0) | T27: =IF(P27*'Unit costs'!$B$7<'Unit costs'!$B$8*'Unit costs'!$B$9,"yes","") | U27: =IF(S27<0.6,"yes","")
A28: 3c. Trigger run (1 turn, gpt-4.1-mini) | B28: per run | C28: median | E28: ='Unit costs'!$B$3*(('Measured usage'!$D$2+'Measured usage'!$D$3+'Measured usage'!$D$4)*((1-'Unit costs'!$B$4)*'Unit prices'!$E$4+'Unit costs'!$B$4*'Unit prices'!$E$5)+'Measured usage'!$D$6*'Unit prices'!$E$6)/1000000 | O28: =SUM(D28:N28) | P28: =O28*'Unit costs'!$B$2 | Q28: =MAX('Unit costs'!$B$8,P28*'Unit costs'!$B$7/'Unit costs'!$B$9) | R28: =Q28*'Unit costs'!$B$9 | S28: =IF(R28>0,1-P28/R28,0) | T28: =IF(P28*'Unit costs'!$B$7<'Unit costs'!$B$8*'Unit costs'!$B$9,"yes","") | U28: =IF(S28<0.6,"yes","")
A29: 3c. Trigger run (1 turn, gpt-4.1-mini) | B29: per run | C29: p90 | E29: ='Unit costs'!$B$3*(('Measured usage'!$D$2+'Measured usage'!$D$3+'Measured usage'!$D$5)*((1-'Unit costs'!$B$4)*'Unit prices'!$E$4+'Unit costs'!$B$4*'Unit prices'!$E$5)+'Measured usage'!$D$7*'Unit prices'!$E$6)/1000000 | O29: =SUM(D29:N29) | P29: =O29*'Unit costs'!$B$2 | Q29: =MAX('Unit costs'!$B$8,P29*'Unit costs'!$B$7/'Unit costs'!$B$9) | R29: =Q29*'Unit costs'!$B$9 | S29: =IF(R29>0,1-P29/R29,0) | T29: =IF(P29*'Unit costs'!$B$7<'Unit costs'!$B$8*'Unit costs'!$B$9,"yes","") | U29: =IF(S29<0.6,"yes","")
A30: 4a. Tool call, ordinary connector (Composio) | B30: per call | C30: median | I30: =1*'Unit prices'!$E$56 | O30: =SUM(D30:N30) | P30: =O30*'Unit costs'!$B$2 | Q30: =MAX('Unit costs'!$B$8,P30*'Unit costs'!$B$7/'Unit costs'!$B$9) | R30: =Q30*'Unit costs'!$B$9 | S30: =IF(R30>0,1-P30/R30,0) | T30: =IF(P30*'Unit costs'!$B$7<'Unit costs'!$B$8*'Unit costs'!$B$9,"yes","") | U30: =IF(S30<0.6,"yes","")
A31: 4a. Tool call, ordinary connector (Composio) | B31: per call | C31: p90 | I31: =1*'Unit prices'!$E$56 | O31: =SUM(D31:N31) | P31: =O31*'Unit costs'!$B$2 | Q31: =MAX('Unit costs'!$B$8,P31*'Unit costs'!$B$7/'Unit costs'!$B$9) | R31: =Q31*'Unit costs'!$B$9 | S31: =IF(R31>0,1-P31/R31,0) | T31: =IF(P31*'Unit costs'!$B$7<'Unit costs'!$B$8*'Unit costs'!$B$9,"yes","") | U31: =IF(S31<0.6,"yes","")
A32: 4b. Tool call, premium connector (Composio; same vendor cost) | B32: per call | C32: median | I32: =1*'Unit prices'!$E$56 | O32: =SUM(D32:N32) | P32: =O32*'Unit costs'!$B$2 | Q32: =MAX('Unit costs'!$B$8,P32*'Unit costs'!$B$7/'Unit costs'!$B$9) | R32: =Q32*'Unit costs'!$B$9 | S32: =IF(R32>0,1-P32/R32,0) | T32: =IF(P32*'Unit costs'!$B$7<'Unit costs'!$B$8*'Unit costs'!$B$9,"yes","") | U32: =IF(S32<0.6,"yes","")
A33: 4b. Tool call, premium connector (Composio; same vendor cost) | B33: per call | C33: p90 | I33: =1*'Unit prices'!$E$56 | O33: =SUM(D33:N33) | P33: =O33*'Unit costs'!$B$2 | Q33: =MAX('Unit costs'!$B$8,P33*'Unit costs'!$B$7/'Unit costs'!$B$9) | R33: =Q33*'Unit costs'!$B$9 | S33: =IF(R33>0,1-P33/R33,0) | T33: =IF(P33*'Unit costs'!$B$7<'Unit costs'!$B$8*'Unit costs'!$B$9,"yes","") | U33: =IF(S33<0.6,"yes","")
A34: 5a. Knowledge ingest, 10-page typed PDF (parse local + embed) | B34: per document | C34: median | J34: ='Unit costs'!$B$3*('Measured usage'!$D$17*'Measured usage'!$D$18*'Measured usage'!$D$19)*'Unit prices'!$E$28/1000000 | O34: =SUM(D34:N34) | P34: =O34*'Unit costs'!$B$2 | Q34: =MAX('Unit costs'!$B$8,P34*'Unit costs'!$B$7/'Unit costs'!$B$9) | R34: =Q34*'Unit costs'!$B$9 | S34: =IF(R34>0,1-P34/R34,0) | T34: =IF(P34*'Unit costs'!$B$7<'Unit costs'!$B$8*'Unit costs'!$B$9,"yes","") | U34: =IF(S34<0.6,"yes","")
A35: 5a. Knowledge ingest, 10-page typed PDF (parse local + embed) | B35: per document | C35: p90 | J35: ='Unit costs'!$B$3*5*('Measured usage'!$D$17*'Measured usage'!$D$18*'Measured usage'!$D$19)*'Unit prices'!$E$28/1000000 | O35: =SUM(D35:N35) | P35: =O35*'Unit costs'!$B$2 | Q35: =MAX('Unit costs'!$B$8,P35*'Unit costs'!$B$7/'Unit costs'!$B$9) | R35: =Q35*'Unit costs'!$B$9 | S35: =IF(R35>0,1-P35/R35,0) | T35: =IF(P35*'Unit costs'!$B$7<'Unit costs'!$B$8*'Unit costs'!$B$9,"yes","") | U35: =IF(S35<0.6,"yes","")
A36: 5b. Knowledge answer (query embed + retrieval + reply, gpt-4.1-mini) | B36: per answer | C36: median | E36: ='Unit costs'!$B$3*(('Measured usage'!$D$2+'Measured usage'!$D$3+'Measured usage'!$D$4+'Measured usage'!$D$20)*((1-'Unit costs'!$B$4)*'Unit prices'!$E$4+'Unit costs'!$B$4*'Unit prices'!$E$5)+'Measured usage'!$D$6*'Unit prices'!$E$6)/1000000 | J36: ='Measured usage'!$D$21*'Unit prices'!$E$28/1000000 | O36: =SUM(D36:N36) | P36: =O36*'Unit costs'!$B$2 | Q36: =MAX('Unit costs'!$B$8,P36*'Unit costs'!$B$7/'Unit costs'!$B$9) | R36: =Q36*'Unit costs'!$B$9 | S36: =IF(R36>0,1-P36/R36,0) | T36: =IF(P36*'Unit costs'!$B$7<'Unit costs'!$B$8*'Unit costs'!$B$9,"yes","") | U36: =IF(S36<0.6,"yes","")
A37: 5b. Knowledge answer (query embed + retrieval + reply, gpt-4.1-mini) | B37: per answer | C37: p90 | E37: ='Unit costs'!$B$3*(('Measured usage'!$D$2+'Measured usage'!$D$3+'Measured usage'!$D$5+2*'Measured usage'!$D$20)*((1-'Unit costs'!$B$4)*'Unit prices'!$E$4+'Unit costs'!$B$4*'Unit prices'!$E$5)+'Measured usage'!$D$7*'Unit prices'!$E$6)/1000000 | J37: ='Measured usage'!$D$21*'Unit prices'!$E$28/1000000 | O37: =SUM(D37:N37) | P37: =O37*'Unit costs'!$B$2 | Q37: =MAX('Unit costs'!$B$8,P37*'Unit costs'!$B$7/'Unit costs'!$B$9) | R37: =Q37*'Unit costs'!$B$9 | S37: =IF(R37>0,1-P37/R37,0) | T37: =IF(P37*'Unit costs'!$B$7<'Unit costs'!$B$8*'Unit costs'!$B$9,"yes","") | U37: =IF(S37<0.6,"yes","")
A38: 6a. Voice minute, Indic stack, India (Sarvam STT + gpt-4.1-mini + Sarvam TTS + Plivo) | B38: per minute | C38: median | D38: =('Unit prices'!$E$29/60)*'Measured usage'!$D$36/'Unit costs'!$B$2 | E38: ='Measured usage'!$D$31*'Unit costs'!$B$3*(('Measured usage'!$D$32+'Measured usage'!$D$33*('Measured usage'!$D$38/60)/2)*((1-'Unit costs'!$B$4)*'Unit prices'!$E$4+'Unit costs'!$B$4*'Unit prices'!$E$5)+'Measured usage'!$D$34*'Unit prices'!$E$6)/1000000 | F38: =('Unit prices'!$E$30/10000)*'Unit costs'!$B$5/'Unit costs'!$B$2 | G38: ='Unit costs'!$B$6*'Unit prices'!$E$47/'Unit costs'!$B$2 | O38: =SUM(D38:N38) | P38: =O38*'Unit costs'!$B$2 | Q38: =MAX('Unit costs'!$B$8,P38*'Unit costs'!$B$7/'Unit costs'!$B$9) | R38: =Q38*'Unit costs'!$B$9 | S38: =IF(R38>0,1-P38/R38,0) | T38: =IF(P38*'Unit costs'!$B$7<'Unit costs'!$B$8*'Unit costs'!$B$9,"yes","") | U38: =IF(S38<0.6,"yes","")
A39: 6a. Voice minute, Indic stack, India (Sarvam STT + gpt-4.1-mini + Sarvam TTS + Plivo) | B39: per minute | C39: p90 | D39: =('Unit prices'!$E$29/60)*'Measured usage'!$D$36/'Unit costs'!$B$2 | E39: ='Measured usage'!$D$31*'Unit costs'!$B$3*(('Measured usage'!$D$32+'Measured usage'!$D$33*('Measured usage'!$D$38/60)/2)*((1-'Unit costs'!$B$4)*'Unit prices'!$E$7+'Unit costs'!$B$4*'Unit prices'!$E$8)+'Measured usage'!$D$34*'Unit prices'!$E$9)/1000000 | F39: =('Unit prices'!$E$30/10000)*'Unit costs'!$B$5/'Unit costs'!$B$2 | G39: ='Unit costs'!$B$6*'Unit prices'!$E$47/'Unit costs'!$B$2 | O39: =SUM(D39:N39) | P39: =O39*'Unit costs'!$B$2 | Q39: =MAX('Unit costs'!$B$8,P39*'Unit costs'!$B$7/'Unit costs'!$B$9) | R39: =Q39*'Unit costs'!$B$9 | S39: =IF(R39>0,1-P39/R39,0) | T39: =IF(P39*'Unit costs'!$B$7<'Unit costs'!$B$8*'Unit costs'!$B$9,"yes","") | U39: =IF(S39<0.6,"yes","")
A40: 6b. Voice minute, Indic stack, inbound India (same vendor rates) | B40: per minute | C40: median | D40: =('Unit prices'!$E$29/60)*'Measured usage'!$D$36/'Unit costs'!$B$2 | E40: ='Measured usage'!$D$31*'Unit costs'!$B$3*(('Measured usage'!$D$32+'Measured usage'!$D$33*('Measured usage'!$D$38/60)/2)*((1-'Unit costs'!$B$4)*'Unit prices'!$E$4+'Unit costs'!$B$4*'Unit prices'!$E$5)+'Measured usage'!$D$34*'Unit prices'!$E$6)/1000000 | F40: =('Unit prices'!$E$30/10000)*'Unit costs'!$B$5/'Unit costs'!$B$2 | G40: ='Unit costs'!$B$6*'Unit prices'!$E$47/'Unit costs'!$B$2 | O40: =SUM(D40:N40) | P40: =O40*'Unit costs'!$B$2 | Q40: =MAX('Unit costs'!$B$8,P40*'Unit costs'!$B$7/'Unit costs'!$B$9) | R40: =Q40*'Unit costs'!$B$9 | S40: =IF(R40>0,1-P40/R40,0) | T40: =IF(P40*'Unit costs'!$B$7<'Unit costs'!$B$8*'Unit costs'!$B$9,"yes","") | U40: =IF(S40<0.6,"yes","")
A41: 6b. Voice minute, Indic stack, inbound India (same vendor rates) | B41: per minute | C41: p90 | D41: =('Unit prices'!$E$29/60)*'Measured usage'!$D$36/'Unit costs'!$B$2 | E41: ='Measured usage'!$D$31*'Unit costs'!$B$3*(('Measured usage'!$D$32+'Measured usage'!$D$33*('Measured usage'!$D$38/60)/2)*((1-'Unit costs'!$B$4)*'Unit prices'!$E$7+'Unit costs'!$B$4*'Unit prices'!$E$8)+'Measured usage'!$D$34*'Unit prices'!$E$9)/1000000 | F41: =('Unit prices'!$E$30/10000)*'Unit costs'!$B$5/'Unit costs'!$B$2 | G41: ='Unit costs'!$B$6*'Unit prices'!$E$47/'Unit costs'!$B$2 | O41: =SUM(D41:N41) | P41: =O41*'Unit costs'!$B$2 | Q41: =MAX('Unit costs'!$B$8,P41*'Unit costs'!$B$7/'Unit costs'!$B$9) | R41: =Q41*'Unit costs'!$B$9 | S41: =IF(R41>0,1-P41/R41,0) | T41: =IF(P41*'Unit costs'!$B$7<'Unit costs'!$B$8*'Unit costs'!$B$9,"yes","") | U41: =IF(S41<0.6,"yes","")
A42: 6c. Voice minute, natural voice (Smallest Lightning Pro TTS), India | B42: per minute | C42: median | D42: =('Unit prices'!$E$29/60)*'Measured usage'!$D$36/'Unit costs'!$B$2 | E42: ='Measured usage'!$D$31*'Unit costs'!$B$3*(('Measured usage'!$D$32+'Measured usage'!$D$33*('Measured usage'!$D$38/60)/2)*((1-'Unit costs'!$B$4)*'Unit prices'!$E$4+'Unit costs'!$B$4*'Unit prices'!$E$5)+'Measured usage'!$D$34*'Unit prices'!$E$6)/1000000 | F42: =('Unit prices'!$E$35/10000)*'Unit costs'!$B$5 | G42: ='Unit costs'!$B$6*'Unit prices'!$E$47/'Unit costs'!$B$2 | O42: =SUM(D42:N42) | P42: =O42*'Unit costs'!$B$2 | Q42: =MAX('Unit costs'!$B$8,P42*'Unit costs'!$B$7/'Unit costs'!$B$9) | R42: =Q42*'Unit costs'!$B$9 | S42: =IF(R42>0,1-P42/R42,0) | T42: =IF(P42*'Unit costs'!$B$7<'Unit costs'!$B$8*'Unit costs'!$B$9,"yes","") | U42: =IF(S42<0.6,"yes","")
...

Sheet Fixed costs
A1: Item | B1: Monthly USD | C1: Monthly INR | D1: Label | E1: Source / note
A2: EC2 production box (instance type assumed t3.xlarge, 4 vCPU / 16 GB) | B2: ='Unit prices'!$E$60*'Measured usage'!$D$45 | C2: =B2*'Unit prices'!$E$2 | D2: assumption | E2: Type not in the repo. The compose stack (api workers, postgres, redis, minio, falkordb, gotenberg, sandbox, coturn, nginx, CI runner) needs at least 4 vCPU / 8 GB per docs/deployment/docker.mdx. Replace with the AWS invoice.
A3: EBS root volume 145 GB gp3 | B3: ='Measured usage'!$D$46*'Unit prices'!$E$59 | C3: =B3*'Unit prices'!$E$2 | D3: measured | E3: Size from scripts/ci_deploy.sh:71; price from AWS EBS pricing.
A4: Egress 200 GB | B4: ='Measured usage'!$D$47*'Unit prices'!$E$61 | C4: =B4*'Unit prices'!$E$2 | D4: assumption | E4: No CloudWatch figures were available.
A5: S3 / backup mirror, 50 GB | B5: =50*'Unit prices'!$E$58 | C5: =B5*'Unit prices'!$E$2 | D5: assumption | E5: MinIO on the box is the default; a mirror bucket is optional (BACKUP_MIRROR_*).
A6: Plivo platform number (verification SMS sender) | B6: ='Unit prices'!$E$48/'Unit prices'!$E$2 | C6: =B6*'Unit prices'!$E$2 | D6: code constant | E6: One number at the code's rental cost.
A7: Meta WhatsApp platform number | B7: 0 | C7: =B7*'Unit prices'!$E$2 | D7: vendor price | E7: Meta does not charge a number rental; per-message only.
A8: Composio plan | B8: 0 | C8: =B8*'Unit prices'!$E$2 | D8: assumption | E8: Hobby tier is free to 100k calls a month; Pro is USD 29 a month (composio.dev/pricing, 29 Sep 2026). Open question which tier the account is on.
A9: PostHog | B9: 0 | C9: =B9*'Unit prices'!$E$2 | D9: assumption | E9: Free tier (1M events a month).
A10: Sentry | B10: 0 | C10: =B10*'Unit prices'!$E$2 | D10: assumption | E10: Developer tier is free; Team is USD 26. Open question whether a DSN is set in production.
A11: Langfuse (self-hosted at langfuse.decibyl.ai) | B11: 0 | C11: =B11*'Unit prices'!$E$2 | D11: assumption | E11: If it is Langfuse Cloud instead, Core is USD 29 a month (langfuse.com/pricing, 29 Sep 2026). Open question.
A12: GitHub Actions | B12: 0 | C12: =B12*'Unit prices'!$E$2 | D12: measured | E12: Self-hosted runner on the production box since 28 Sep 2026; spending limit to be set to USD 0.
A13: Domain, DNS, Cloudflare | B13: 2 | C13: =B13*'Unit prices'!$E$2 | D13: assumption | E13: decibyl.ai renewal amortised; Cloudflare free plan.
A14: SMTP relay | B14: 0 | C14: =B14*'Unit prices'!$E$2 | D14: assumption | E14: Vendor unnamed in code; most relays are free below 3k mails a month.
A15: Razorpay | B15: 0 | C15: =B15*'Unit prices'!$E$2 | D15: vendor price | E15: No fixed fee; MDR is variable and modelled per plan on the Plan margins sheet.
A16: Total fixed per month | B16: =SUM(B2:B15) | C16: =SUM(C2:C15)
A18: Marginal cost of one extra workspace per month
A19: Storage (GB assumed per workspace x S3 price) | B19: ='Measured usage'!$D$43*'Unit prices'!$E$58 | C19: =B19*'Unit prices'!$E$2
A20: Database rows, background jobs, Redis (share of the box) | B20: =B2/500 | C20: =B20*'Unit prices'!$E$2 | E20: Assumption: one box carries about 500 light workspaces before the next box (docs/deployment/scaling.mdx sizes by voice concurrency, not by workspace).
A21: Marginal cost per extra workspace | B21: =B19+B20 | C21: =B21*'Unit prices'!$E$2
A23: Fixed cost allocated per paying workspace
A24: Paying workspaces | B24: Fixed USD / workspace | C24: Fixed INR / workspace | E24: Note
A25: 50 | B25: =$B$16/A25 | C25: =$C$16/A25 | E25: At 1,000 workspaces a second box is likely; the total here stays at one box, so the 1,000 figure is a floor.
A26: 200 | B26: =$B$16/A26 | C26: =$C$16/A26 | E26: At 1,000 workspaces a second box is likely; the total here stays at one box, so the 1,000 figure is a floor.
A27: 1000 | B27: =$B$16/A27 | C27: =$C$16/A27 | E27: At 1,000 workspaces a second box is likely; the total here stays at one box, so the 1,000 figure is a floor.

Sheet Plan margins
A1: Proposed plans (from the audit prompt; not live)
A2: Plan | B2: Price INR | C2: Price USD | D2: Credits | E2: Chat per day | F2: Builder msgs per month | G2: Agents | H2: Chat cost median INR (default model) | I2: Chat cost INR if opus ran inside the allowance (p90) | J2: Builder cost median INR | K2: Cost per credit spent INR | L2: Chat cost p90 INR (default model) | M2: Builder cost p90 INR
A3: Starter | B3: 3999 | C3: 59 | D3: 3000 | E3: 30 | F3: 100 | G3: 2 | H3: ='Unit costs'!$P$14 | I3: ='Unit costs'!$P$19 | J3: ='Unit costs'!$P$22 | K3: ='Unit costs'!$B$9/'Unit costs'!$B$7 | L3: ='Unit costs'!$P$15 | M3: ='Unit costs'!$P$23
A4: Growth | B4: 14999 | C4: 199 | D4: 12000 | E4: 100 | F4: 500 | G4: 10 | H4: ='Unit costs'!$P$14 | I4: ='Unit costs'!$P$19 | J4: ='Unit costs'!$P$22 | K4: ='Unit costs'!$B$9/'Unit costs'!$B$7 | L4: ='Unit costs'!$P$15 | M4: ='Unit costs'!$P$23
A5: Scale | B5: 39999 | C5: 499 | D5: 32000 | E5: 300 | F5: 1500 | G5: 50 | H5: ='Unit costs'!$P$14 | I5: ='Unit costs'!$P$19 | J5: ='Unit costs'!$P$22 | K5: ='Unit costs'!$B$9/'Unit costs'!$B$7 | L5: ='Unit costs'!$P$15 | M5: ='Unit costs'!$P$23
A8: Gross margin by utilisation (India price, INR). Cost = u x (chat/day x 30 x chat cost + builder msgs x builder cost + credits x cost per credit). Razorpay MDR deducted from revenue.
A9: Plan | B9: Case | C9: Utilisation | D9: Revenue INR (net of MDR) | E9: Chat cost INR | F9: Builder cost INR | G9: Credits cost INR | H9: Total variable INR | I9: Gross margin | J9: Gross margin < 60%? | K9: Fixed alloc at 50 ws INR | L9: Margin after fixed (50 ws) | M9: Margin after fixed (200 ws) | N9: Global revenue INR (USD price x FX, net of MDR) | O9: Global gross margin
A10: Starter | B10: 25% use | C10: 0.25 | D10: =$B$3*(1-'Unit prices'!$E$57) | E10: =C10*$E$3*30*$H$3 | F10: =C10*$F$3*$J$3 | G10: =C10*$D$3*$K$3 | H10: =E10+F10+G10 | I10: =1-H10/D10 | J10: =IF(I10<0.6,"yes","") | K10: ='Fixed costs'!$C$25 | L10: =1-(H10+K10)/D10 | M10: =1-(H10+'Fixed costs'!$C$26)/D10 | N10: =$C$3*'Unit costs'!$B$2*(1-'Unit prices'!$E$57) | O10: =1-H10/N10
A11: Starter | B11: 50% use | C11: 0.5 | D11: =$B$3*(1-'Unit prices'!$E$57) | E11: =C11*$E$3*30*$H$3 | F11: =C11*$F$3*$J$3 | G11: =C11*$D$3*$K$3 | H11: =E11+F11+G11 | I11: =1-H11/D11 | J11: =IF(I11<0.6,"yes","") | K11: ='Fixed costs'!$C$25 | L11: =1-(H11+K11)/D11 | M11: =1-(H11+'Fixed costs'!$C$26)/D11 | N11: =$C$3*'Unit costs'!$B$2*(1-'Unit prices'!$E$57) | O11: =1-H11/N11
A12: Starter | B12: 100% use | C12: 1 | D12: =$B$3*(1-'Unit prices'!$E$57) | E12: =C12*$E$3*30*$H$3 | F12: =C12*$F$3*$J$3 | G12: =C12*$D$3*$K$3 | H12: =E12+F12+G12 | I12: =1-H12/D12 | J12: =IF(I12<0.6,"yes","") | K12: ='Fixed costs'!$C$25 | L12: =1-(H12+K12)/D12 | M12: =1-(H12+'Fixed costs'!$C$26)/D12 | N12: =$C$3*'Unit costs'!$B$2*(1-'Unit prices'!$E$57) | O12: =1-H12/N12
A13: Starter | B13: worst case: all used, p90 on the default model | C13: 1 | D13: =$B$3*(1-'Unit prices'!$E$57) | E13: =C13*$E$3*30*$L$3 | F13: =C13*$F$3*$M$3 | G13: =C13*$D$3*$K$3 | H13: =E13+F13+G13 | I13: =1-H13/D13 | J13: =IF(I13<0.6,"yes","") | K13: ='Fixed costs'!$C$25 | L13: =1-(H13+K13)/D13 | M13: =1-(H13+'Fixed costs'!$C$26)/D13 | N13: =$C$3*'Unit costs'!$B$2*(1-'Unit prices'!$E$57) | O13: =1-H13/N13
A14: Starter | B14: if opus chat ran inside the allowance (rule says premium chat is credits) | C14: 1 | D14: =$B$3*(1-'Unit prices'!$E$57) | E14: =C14*$E$3*30*$I$3 | F14: =C14*$F$3*$M$3 | G14: =C14*$D$3*$K$3 | H14: =E14+F14+G14 | I14: =1-H14/D14 | J14: =IF(I14<0.6,"yes","") | K14: ='Fixed costs'!$C$25 | L14: =1-(H14+K14)/D14 | M14: =1-(H14+'Fixed costs'!$C$26)/D14 | N14: =$C$3*'Unit costs'!$B$2*(1-'Unit prices'!$E$57) | O14: =1-H14/N14
A15: Growth | B15: 25% use | C15: 0.25 | D15: =$B$4*(1-'Unit prices'!$E$57) | E15: =C15*$E$4*30*$H$4 | F15: =C15*$F$4*$J$4 | G15: =C15*$D$4*$K$4 | H15: =E15+F15+G15 | I15: =1-H15/D15 | J15: =IF(I15<0.6,"yes","") | K15: ='Fixed costs'!$C$25 | L15: =1-(H15+K15)/D15 | M15: =1-(H15+'Fixed costs'!$C$26)/D15 | N15: =$C$4*'Unit costs'!$B$2*(1-'Unit prices'!$E$57) | O15: =1-H15/N15
A16: Growth | B16: 50% use | C16: 0.5 | D16: =$B$4*(1-'Unit prices'!$E$57) | E16: =C16*$E$4*30*$H$4 | F16: =C16*$F$4*$J$4 | G16: =C16*$D$4*$K$4 | H16: =E16+F16+G16 | I16: =1-H16/D16 | J16: =IF(I16<0.6,"yes","") | K16: ='Fixed costs'!$C$25 | L16: =1-(H16+K16)/D16 | M16: =1-(H16+'Fixed costs'!$C$26)/D16 | N16: =$C$4*'Unit costs'!$B$2*(1-'Unit prices'!$E$57) | O16: =1-H16/N16
A17: Growth | B17: 100% use | C17: 1 | D17: =$B$4*(1-'Unit prices'!$E$57) | E17: =C17*$E$4*30*$H$4 | F17: =C17*$F$4*$J$4 | G17: =C17*$D$4*$K$4 | H17: =E17+F17+G17 | I17: =1-H17/D17 | J17: =IF(I17<0.6,"yes","") | K17: ='Fixed costs'!$C$25 | L17: =1-(H17+K17)/D17 | M17: =1-(H17+'Fixed costs'!$C$26)/D17 | N17: =$C$4*'Unit costs'!$B$2*(1-'Unit prices'!$E$57) | O17: =1-H17/N17
A18: Growth | B18: worst case: all used, p90 on the default model | C18: 1 | D18: =$B$4*(1-'Unit prices'!$E$57) | E18: =C18*$E$4*30*$L$4 | F18: =C18*$F$4*$M$4 | G18: =C18*$D$4*$K$4 | H18: =E18+F18+G18 | I18: =1-H18/D18 | J18: =IF(I18<0.6,"yes","") | K18: ='Fixed costs'!$C$25 | L18: =1-(H18+K18)/D18 | M18: =1-(H18+'Fixed costs'!$C$26)/D18 | N18: =$C$4*'Unit costs'!$B$2*(1-'Unit prices'!$E$57) | O18: =1-H18/N18
A19: Growth | B19: if opus chat ran inside the allowance (rule says premium chat is credits) | C19: 1 | D19: =$B$4*(1-'Unit prices'!$E$57) | E19: =C19*$E$4*30*$I$4 | F19: =C19*$F$4*$M$4 | G19: =C19*$D$4*$K$4 | H19: =E19+F19+G19 | I19: =1-H19/D19 | J19: =IF(I19<0.6,"yes","") | K19: ='Fixed costs'!$C$25 | L19: =1-(H19+K19)/D19 | M19: =1-(H19+'Fixed costs'!$C$26)/D19 | N19: =$C$4*'Unit costs'!$B$2*(1-'Unit prices'!$E$57) | O19: =1-H19/N19
A20: Scale | B20: 25% use | C20: 0.25 | D20: =$B$5*(1-'Unit prices'!$E$57) | E20: =C20*$E$5*30*$H$5 | F20: =C20*$F$5*$J$5 | G20: =C20*$D$5*$K$5 | H20: =E20+F20+G20 | I20: =1-H20/D20 | J20: =IF(I20<0.6,"yes","") | K20: ='Fixed costs'!$C$25 | L20: =1-(H20+K20)/D20 | M20: =1-(H20+'Fixed costs'!$C$26)/D20 | N20: =$C$5*'Unit costs'!$B$2*(1-'Unit prices'!$E$57) | O20: =1-H20/N20
A21: Scale | B21: 50% use | C21: 0.5 | D21: =$B$5*(1-'Unit prices'!$E$57) | E21: =C21*$E$5*30*$H$5 | F21: =C21*$F$5*$J$5 | G21: =C21*$D$5*$K$5 | H21: =E21+F21+G21 | I21: =1-H21/D21 | J21: =IF(I21<0.6,"yes","") | K21: ='Fixed costs'!$C$25 | L21: =1-(H21+K21)/D21 | M21: =1-(H21+'Fixed costs'!$C$26)/D21 | N21: =$C$5*'Unit costs'!$B$2*(1-'Unit prices'!$E$57) | O21: =1-H21/N21
A22: Scale | B22: 100% use | C22: 1 | D22: =$B$5*(1-'Unit prices'!$E$57) | E22: =C22*$E$5*30*$H$5 | F22: =C22*$F$5*$J$5 | G22: =C22*$D$5*$K$5 | H22: =E22+F22+G22 | I22: =1-H22/D22 | J22: =IF(I22<0.6,"yes","") | K22: ='Fixed costs'!$C$25 | L22: =1-(H22+K22)/D22 | M22: =1-(H22+'Fixed costs'!$C$26)/D22 | N22: =$C$5*'Unit costs'!$B$2*(1-'Unit prices'!$E$57) | O22: =1-H22/N22
A23: Scale | B23: worst case: all used, p90 on the default model | C23: 1 | D23: =$B$5*(1-'Unit prices'!$E$57) | E23: =C23*$E$5*30*$L$5 | F23: =C23*$F$5*$M$5 | G23: =C23*$D$5*$K$5 | H23: =E23+F23+G23 | I23: =1-H23/D23 | J23: =IF(I23<0.6,"yes","") | K23: ='Fixed costs'!$C$25 | L23: =1-(H23+K23)/D23 | M23: =1-(H23+'Fixed costs'!$C$26)/D23 | N23: =$C$5*'Unit costs'!$B$2*(1-'Unit prices'!$E$57) | O23: =1-H23/N23
A24: Scale | B24: if opus chat ran inside the allowance (rule says premium chat is credits) | C24: 1 | D24: =$B$5*(1-'Unit prices'!$E$57) | E24: =C24*$E$5*30*$I$5 | F24: =C24*$F$5*$M$5 | G24: =C24*$D$5*$K$5 | H24: =E24+F24+G24 | I24: =1-H24/D24 | J24: =IF(I24<0.6,"yes","") | K24: ='Fixed costs'!$C$25 | L24: =1-(H24+K24)/D24 | M24: =1-(H24+'Fixed costs'!$C$26)/D24 | N24: =$C$5*'Unit costs'!$B$2*(1-'Unit prices'!$E$57) | O24: =1-H24/N24
A26: Credit pack: 5,000 credits for INR 4,500 / USD 55
A27: Pack | B27: Price INR | C27: Price USD | D27: Credits | E27: Cost if all spent at cost x multiple (INR) | F27: Gross margin India | G27: Global revenue INR | H27: Gross margin global
A28: 5,000 credits | B28: 4500 | C28: 55 | D28: 5000 | E28: =D28*'Unit costs'!$B$9/'Unit costs'!$B$7 | F28: =1-E28/(B28*(1-'Unit prices'!$E$57)) | G28: =C28*'Unit costs'!$B$2*(1-'Unit prices'!$E$57) | H28: =1-E28/G28
A30: How many actions a plan's credits buy at the proposed prices (median cost x multiple, minimum applied)
A31: Plan | B31: Credits | C31: Chat messages (default) | D31: Chat messages (gpt-5) | E31: Task runs | F31: Knowledge answers | G31: Tool calls (at minimum) | H31: WhatsApp utility (at minimum)
A32: Starter | B32: =$D$3 | C32: =ROUNDDOWN(B32/'Unit costs'!$Q$14,0) | D32: =ROUNDDOWN(B32/'Unit costs'!$Q$16,0) | E32: =ROUNDDOWN(B32/'Unit costs'!$Q$24,0) | F32: =ROUNDDOWN(B32/'Unit costs'!$Q$36,0) | G32: =ROUNDDOWN(B32/'Unit costs'!$Q$30,0) | H32: =ROUNDDOWN(B32/'Unit costs'!$Q$54,0)
A33: Growth | B33: =$D$4 | C33: =ROUNDDOWN(B33/'Unit costs'!$Q$14,0) | D33: =ROUNDDOWN(B33/'Unit costs'!$Q$16,0) | E33: =ROUNDDOWN(B33/'Unit costs'!$Q$24,0) | F33: =ROUNDDOWN(B33/'Unit costs'!$Q$36,0) | G33: =ROUNDDOWN(B33/'Unit costs'!$Q$30,0) | H33: =ROUNDDOWN(B33/'Unit costs'!$Q$54,0)
A34: Scale | B34: =$D$5 | C34: =ROUNDDOWN(B34/'Unit costs'!$Q$14,0) | D34: =ROUNDDOWN(B34/'Unit costs'!$Q$16,0) | E34: =ROUNDDOWN(B34/'Unit costs'!$Q$24,0) | F34: =ROUNDDOWN(B34/'Unit costs'!$Q$36,0) | G34: =ROUNDDOWN(B34/'Unit costs'!$Q$30,0) | H34: =ROUNDDOWN(B34/'Unit costs'!$Q$54,0)

Sheet Voice margins
A1: Proposed voice prices (all-in, from the audit prompt)
A2: Offer | B2: Price per minute INR | C2: Price per minute USD | D2: Basis
A3: India pay-as-you-go | B3: 6 | C3: =B3/'Unit costs'!$B$2 | D3: INR 6/min
A4: India pack 500 min at INR 2,750 | B4: 5.5 | C4: =B4/'Unit costs'!$B$2 | D4: INR 5.50/min
A5: India pack 2,000 min at INR 10,000 | B5: 5 | C5: =B5/'Unit costs'!$B$2 | D5: INR 5.00/min
A6: Global pay-as-you-go | B6: =C6*'Unit costs'!$B$2 | C6: 0.18 | D6: USD 0.18/min
A7: Global pack 500 min at USD 80 | B7: =C7*'Unit costs'!$B$2 | C7: 0.16 | D7: USD 0.16/min
A8: Global pack 2,000 min at USD 300 | B8: =C8*'Unit costs'!$B$2 | C8: 0.15 | D8: USD 0.15/min
A10: Gross margin per minute by stack and offer (cost from Unit costs, median case; MDR deducted from the price)
A11: Stack | B11: Offer | C11: Cost INR / min | D11: Price INR / min (net of MDR) | E11: Gross margin | F11: Margin < 60%? | G11: Cost p90 INR / min | H11: Margin at p90
A12: 6a. Voice minute, Indic stack, India (Sarvam STT + gpt-4.1-mini + Sarvam TTS + Plivo) | B12: India pay-as-you-go | C12: ='Unit costs'!$P$38 | D12: =$B$3*(1-'Unit prices'!$E$57) | E12: =1-C12/D12 | F12: =IF(E12<0.6,"yes","") | G12: ='Unit costs'!$P$39 | H12: =1-G12/D12
A13: 6a. Voice minute, Indic stack, India (Sarvam STT + gpt-4.1-mini + Sarvam TTS + Plivo) | B13: India pack 500 min at INR 2,750 | C13: ='Unit costs'!$P$38 | D13: =$B$4*(1-'Unit prices'!$E$57) | E13: =1-C13/D13 | F13: =IF(E13<0.6,"yes","") | G13: ='Unit costs'!$P$39 | H13: =1-G13/D13
A14: 6a. Voice minute, Indic stack, India (Sarvam STT + gpt-4.1-mini + Sarvam TTS + Plivo) | B14: India pack 2,000 min at INR 10,000 | C14: ='Unit costs'!$P$38 | D14: =$B$5*(1-'Unit prices'!$E$57) | E14: =1-C14/D14 | F14: =IF(E14<0.6,"yes","") | G14: ='Unit costs'!$P$39 | H14: =1-G14/D14
A15: 6c. Voice minute, natural voice (Smallest Lightning Pro TTS), India | B15: India pay-as-you-go | C15: ='Unit costs'!$P$42 | D15: =$B$3*(1-'Unit prices'!$E$57) | E15: =1-C15/D15 | F15: =IF(E15<0.6,"yes","") | G15: ='Unit costs'!$P$43 | H15: =1-G15/D15
A16: 6c. Voice minute, natural voice (Smallest Lightning Pro TTS), India | B16: India pack 500 min at INR 2,750 | C16: ='Unit costs'!$P$42 | D16: =$B$4*(1-'Unit prices'!$E$57) | E16: =1-C16/D16 | F16: =IF(E16<0.6,"yes","") | G16: ='Unit costs'!$P$43 | H16: =1-G16/D16
A17: 6c. Voice minute, natural voice (Smallest Lightning Pro TTS), India | B17: India pack 2,000 min at INR 10,000 | C17: ='Unit costs'!$P$42 | D17: =$B$5*(1-'Unit prices'!$E$57) | E17: =1-C17/D17 | F17: =IF(E17<0.6,"yes","") | G17: ='Unit costs'!$P$43 | H17: =1-G17/D17
A18: 6d. Voice minute, premium voice (ElevenLabs Flash TTS), India | B18: India pay-as-you-go | C18: ='Unit costs'!$P$44 | D18: =$B$3*(1-'Unit prices'!$E$57) | E18: =1-C18/D18 | F18: =IF(E18<0.6,"yes","") | G18: ='Unit costs'!$P$45 | H18: =1-G18/D18
A19: 6d. Voice minute, premium voice (ElevenLabs Flash TTS), India | B19: India pack 500 min at INR 2,750 | C19: ='Unit costs'!$P$44 | D19: =$B$4*(1-'Unit prices'!$E$57) | E19: =1-C19/D19 | F19: =IF(E19<0.6,"yes","") | G19: ='Unit costs'!$P$45 | H19: =1-G19/D19
A20: 6d. Voice minute, premium voice (ElevenLabs Flash TTS), India | B20: India pack 2,000 min at INR 10,000 | C20: ='Unit costs'!$P$44 | D20: =$B$5*(1-'Unit prices'!$E$57) | E20: =1-C20/D20 | F20: =IF(E20<0.6,"yes","") | G20: ='Unit costs'!$P$45 | H20: =1-G20/D20
A21: 6e. Voice minute, Gemini Live, India | B21: India pay-as-you-go | C21: ='Unit costs'!$P$46 | D21: =$B$3*(1-'Unit prices'!$E$57) | E21: =1-C21/D21 | F21: =IF(E21<0.6,"yes","") | G21: ='Unit costs'!$P$47 | H21: =1-G21/D21
A22: 6e. Voice minute, Gemini Live, India | B22: India pack 500 min at INR 2,750 | C22: ='Unit costs'!$P$46 | D22: =$B$4*(1-'Unit prices'!$E$57) | E22: =1-C22/D22 | F22: =IF(E22<0.6,"yes","") | G22: ='Unit costs'!$P$47 | H22: =1-G22/D22
A23: 6e. Voice minute, Gemini Live, India | B23: India pack 2,000 min at INR 10,000 | C23: ='Unit costs'!$P$46 | D23: =$B$5*(1-'Unit prices'!$E$57) | E23: =1-C23/D23 | F23: =IF(E23<0.6,"yes","") | G23: ='Unit costs'!$P$47 | H23: =1-G23/D23
A24: 6f. Voice minute, OpenAI realtime premium, India | B24: India pay-as-you-go | C24: ='Unit costs'!$P$48 | D24: =$B$3*(1-'Unit prices'!$E$57) | E24: =1-C24/D24 | F24: =IF(E24<0.6,"yes","") | G24: ='Unit costs'!$P$49 | H24: =1-G24/D24
A25: 6f. Voice minute, OpenAI realtime premium, India | B25: India pack 500 min at INR 2,750 | C25: ='Unit costs'!$P$48 | D25: =$B$4*(1-'Unit prices'!$E$57) | E25: =1-C25/D25 | F25: =IF(E25<0.6,"yes","") | G25: ='Unit costs'!$P$49 | H25: =1-G25/D25
A26: 6f. Voice minute, OpenAI realtime premium, India | B26: India pack 2,000 min at INR 10,000 | C26: ='Unit costs'!$P$48 | D26: =$B$5*(1-'Unit prices'!$E$57) | E26: =1-C26/D26 | F26: =IF(E26<0.6,"yes","") | G26: ='Unit costs'!$P$49 | H26: =1-G26/D26
A27: 6g. Voice minute, overseas (Deepgram Flux + gpt-4.1-mini + ElevenLabs + Twilio US) | B27: Global pay-as-you-go | C27: ='Unit costs'!$P$50 | D27: =$B$6*(1-'Unit prices'!$E$57) | E27: =1-C27/D27 | F27: =IF(E27<0.6,"yes","") | G27: ='Unit costs'!$P$51 | H27: =1-G27/D27
A28: 6g. Voice minute, overseas (Deepgram Flux + gpt-4.1-mini + ElevenLabs + Twilio US) | B28: Global pack 500 min at USD 80 | C28: ='Unit costs'!$P$50 | D28: =$B$7*(1-'Unit prices'!$E$57) | E28: =1-C28/D28 | F28: =IF(E28<0.6,"yes","") | G28: ='Unit costs'!$P$51 | H28: =1-G28/D28
